Workbook

Sheet SSS Contribution Table
A1: Range of Compensation | C1: EE Contribution | D1: ER
A2: 12750 | B2: 13249.99 | C2: 650 | D2: 1310
A3: 13250 | B3: 13749.99 | C3: 675 | D3: 1360
A4: 13750 | B4: 14249.99 | C4: 700 | D4: 1410
A5: 14250 | B5: 14749.99 | C5: 725 | D5: 1460
A6: 14750 | B6: 15249.99 | C6: 750 | D6: 1530
A7: 15250 | B7: 15749.99 | C7: 775 | D7: 1580
A8: 15750 | B8: 16249.99 | C8: 800 | D8: 1630
A9: 16250 | B9: 16749.99 | C9: 825 | D9: 1680
A10: 16750 | B10: 17249.99 | C10: 850 | D10: 1730
A11: 17250 | B11: 17749.99 | C11: 875 | D11: 1780
A12: 17750 | B12: 18249.99 | C12: 900 | D12: 1830
A13: 18250 | B13: 18749.99 | C13: 925 | D13: 1880
... A45: 34250 | B45: 34749.99 | C45: 1725 | D45: 3480
A46: 34750 | C46: 1750 | D46: 3530

Sheet Total Hours - Summary
A1: Emp ID | B1: Employee Name | C1: 45946 | D1: 45947 | E1: 45948 | F1: 45949 | G1: 45950 | H1: 45951 | I1: 45952 | J1: 45953 | K1: 45954 | L1: 45955 | M1: 45956 | N1: 45957 | O1: 45958 | P1: 45959 | Q1: 45960 | R1: 45961 | S1: Grand Total
A2: 01100240 | B2: Abegail Mandras | C2: 8 | D2: 8 | G2: 8 | H2: 8 | I2: 8 | J2: 8 | K2: 8 | N2: 8 | O2: 8 | P2: 8 | Q2: 8 | R2: 8 | S2: =SUM(C2:R2) -> 96
A3: 01100277 | B3: Adrian Lawat | C3: 8 | D3: 8 | G3: 7.9 | H3: 8 | I3: 7.98 | J3: 8 | K3: 8 | N3: 7.44 | O3: 6.91 | P3: 7.66 | Q3: 8 | R3: 6.01 | S3: =SUM(C3:R3) -> 91.9
A4: 02100100 | B4: Aillen Joy Largo | C4: 8 | D4: 8 | G4: 8 | H4: 7.96 | I4: 5.12 | J4: 8 | K4: 8 | N4: 8 | O4: 8 | P4: 8 | Q4: 8 | R4: 8 | S4: =SUM(C4:R4) -> 93.08
A5: 01100328 | B5: Al Mario Bahala | C5: 7.17 | S5: =SUM(C5:R5) -> 7.17
A6: 02100334 | B6: Alvin Lozada | C6: 8 | D6: 8 | G6: 8 | H6: 8 | I6: 8 | J6: 8 | K6: 8 | N6: 8 | O6: 8 | P6: 8 | Q6: 8 | R6: 8 | S6: =SUM(C6:R6) -> 96
A7: 01100101 | B7: Andrea Ceniza | C7: 8 | D7: 8 | G7: 8 | H7: 8 | I7: 8 | J7: 8 | K7: 8 | N7: 8 | O7: 8 | P7: 8 | Q7: 8 | R7: 8 | S7: =SUM(C7:R7) -> 96
A8: 02100103 | B8: Angelica Paligsa | C8: 8 | D8: 8 | H8: 8 | I8: 8 | J8: 8 | K8: 8 | N8: 8 | O8: 8 | P8: 8 | Q8: 8 | R8: 8 | S8: =SUM(C8:R8) -> 88
A9: 02100104 | B9: Ann Lou Minguito | C9: 8 | D9: 7.98 | E9: 5.5 | G9: 8 | H9: 8 | I9: 8 | J9: 8 | K9: 7.98 | N9: 8 | O9: 8 | P9: 8 | Q9: 8 | R9: 8 | S9: =SUM(C9:R9) -> 101.46
A10: 02200105 | B10: Anna Marie Tabares | C10: 8 | D10: 8 | G10: 8 | H10: 5.67 | I10: 8 | J10: 8 | K10: 8 | N10: 8 | P10: 8 | Q10: 8 | R10: 8 | S10: =SUM(C10:R10)-R10-D10 -> 69.67
A11: 02100106 | B11: Anna Mica Ella Punongbayan | C11: 8 | D11: 7.99 | G11: 7.45 | H11: 8 | I11: 7.62 | J11: 7.39 | K11: 7.03 | N11: 7.72 | O11: 8 | P11: 7.5 | Q11: 6.8 | R11: 8 | S11: =SUM(C11:R11)-R11-D11 -> 75.51
A12: 02100227 | B12: April Jane Elnar | C12: 8 | D12: 8 | G12: 8 | H12: 8 | I12: 8 | J12: 8 | K12: 8 | N12: 8 | O12: 8 | P12: 8 | Q12: 8 | R12: 8 | S12: =SUM(C12:R12) -> 96
A13: 02100194 | B13: April Sanchez | D13: 8 | H13: 8 | I13: 8 | J13: 8 | K13: 8 | N13: 8 | Q13: 8 | R13: 7.9 | S13: =SUM(C13:R13) -> 63.9
A14: 01100218 | B14: Aquilyn Dayan A. Adlit | C14: 8 | D14: 8 | G14: 8 | H14: 8 | I14: 8 | J14: 8 | K14: 8 | N14: 8 | O14: 8 | P14: 8 | Q14: 8 | R14: 8 | S14: =SUM(C14:R14) -> 96
A15: 02100327 | B15: Ardeth James Ortega | C15: 8 | D15: 8 | G15: 8 | H15: 8 | I15: 8 | J15: 8 | K15: 8 | O15: 8 | P15: 8 | Q15: 8 | R15: 8 | S15: =SUM(C15:R15) -> 88
A16: 02100107 | B16: Brenda Mae T. Bacurnay | C16: 8 | D16: 8 | G16: 8 | H16: 8 | I16: 8 | J16: 8 | K16: 8 | N16: 8 | O16: 8 | P16: 8 | Q16: 8 | R16: 8 | S16: =SUM(C16:R16) -> 96
A17: 01100271 | B17: Buenagen Bagundol | C17: 8 | F17: 8 | G17: 8 | H17: 8 | I17: 8 | J17: 8 | K17: 8 | N17: 8 | O17: 8 | P17: 8 | S17: =SUM(C17:R17) -> 80
A18: 01100108 | B18: Camela Torrate | C18: 8 | D18: 8 | G18: 8 | H18: 8 | I18: 8 | J18: 8 | K18: 8 | O18: 8 | P18: 8 | Q18: 8 | R18: 8 | S18: =SUM(C18:R18) -> 88
A19: 02100109 | B19: Candice Kate Velasco | C19: 8 | D19: 8 | G19: 8 | H19: 8 | I19: 8 | J19: 8 | K19: 8 | N19: 8 | O19: 8 | P19: 8 | Q19: 8 | R19: 8 | S19: =SUM(C19:R19) -> 96
A20: 02100294 | B20: Carlo John Rubio | C20: 8 | D20: 8 | G20: 8 | H20: 8 | I20: 8 | J20: 8 | K20: 8 | N20: 8 | O20: 3.89 | P20: 8 | Q20: 8 | R20: 8 | S20: =SUM(C20:R20) -> 91.89
A21: 01100270 | B21: Catherine Vergara | C21: 7.89 | D21: 8 | G21: 8 | H21: 8 | I21: 8 | J21: 8 | K21: 8 | N21: 8 | O21: 8 | P21: 7.97 | Q21: 8 | R21: 7.88 | S21: =SUM(C21:R21) -> 95.74
A22: 01100220 | B22: Christian Pagobo | C22: 8 | D22: 8 | G22: 8 | H22: 8 | I22: 8 | J22: 8 | K22: 8 | N22: 8 | O22: 8 | P22: 8 | Q22: 8 | R22: 8 | S22: =SUM(C22:R22) -> 96
A23: 01100112 | B23: Crislyn Cuizon | C23: 8 | D23: 8 | G23: 8 | H23: 8 | I23: 8 | J23: 8 | K23: 8 | N23: 8 | O23: 8 | P23: 8 | Q23: 8 | R23: 8 | S23: =SUM(C23:R23) -> 96
A24: 01100329 | B24: Cyriline Vergara | C24: 8 | D24: 8 | G24: 8 | H24: 8 | I24: 8 | M24: 8 | N24: 8 | O24: 8 | P24: 8 | S24: =SUM(C24:R24) -> 72
A25: 01100113 | B25: Demie Marie Medalle | C25: 8 | D25: 8 | G25: 8 | H25: 8 | I25: 8 | J25: 0 | K25: 8 | N25: 8 | O25: 8 | P25: 8 | Q25: 8 | R25: 8 | S25: =SUM(C25:R25) -> 88
A26: 01100115 | B26: Dharlene G. Bendanillo | C26: 8 | D26: 8 | G26: 8 | H26: 8 | I26: 8 | J26: 8 | K26: 8 | N26: 8 | O26: 8 | P26: 8 | Q26: 8 | R26: 8 | S26: =SUM(C26:R26) -> 96
A27: 01100116 | B27: Donald Bacanaya | C27: 8 | D27: 8 | G27: 8 | H27: 8 | I27: 8 | J27: 8 | K27: 8 | N27: 8 | O27: 8 | P27: 8 | Q27: 8 | R27: 8 | S27: =SUM(C27:R27) -> 96
A28: 01100253 | B28: Ericka Dorreen Amores - Abejero | C28: 8 | D28: 8 | G28: 8 | H28: 7.92 | I28: 8 | J28: 8 | K28: 8 | N28: 8 | O28: 8 | P28: 6.9 | Q28: 7.49 | R28: 7.57 | S28: =SUM(C28:R28) -> 93.88
A29: 02100117 | B29: Ernesto F. Roquin Jr. | C29: 8 | D29: 8 | G29: 8 | H29: 8 | I29: 8 | J29: 8 | K29: 8 | N29: 8 | O29: 8 | P29: 8 | Q29: 8 | R29: 8 | S29: =SUM(C29:R29) -> 96
A30: 01100118 | B30: Fame Diez | C30: 8 | D30: 8 | G30: 8 | H30: 8 | I30: 8 | J30: 8 | N30: 8 | O30: 8 | P30: 8 | Q30: 8 | R30: 8 | S30: =SUM(C30:R30) -> 88
A31: 01100221 | B31: Farrah Jean Vildosola | C31: 8 | D31: 8 | G31: 8 | H31: 8 | I31: 8 | J31: 8 | K31: 8 | N31: 8 | O31: 8 | P31: 8 | Q31: 8 | R31: 8 | S31: =SUM(C31:R31) -> 96
A32: 02100119 | B32: Ferreh Jane Vilos | C32: 8 | D32: 8 | G32: 8 | H32: 8 | I32: 8 | J32: 8 | K32: 8 | N32: 8 | O32: 8 | P32: 8 | Q32: 8 | R32: 8 | S32: =SUM(C32:R32) -> 96
A33: 02100120 | B33: Flint Kaynon Balmadres | C33: 8 | D33: 8 | G33: 8 | H33: 8 | I33: 8 | J33: 8 | K33: 8 | N33: 8 | O33: 8 | P33: 8 | Q33: 8 | R33: 8 | S33: =SUM(C33:R33) -> 96
A34: 01100217 | B34: Franklyn Jay Talisic | C34: 8 | D34: 8 | G34: 8 | H34: 8 | I34: 8 | J34: 8 | K34: 8 | N34: 7.98 | O34: 8 | P34: 7.99 | Q34: 8 | R34: 7.93 | S34: =SUM(C34:R34) -> 95.9
A35: 02100121 | B35: Fritzyl D. Lorico | C35: 8 | D35: 8 | G35: 8 | H35: 8 | I35: 8 | J35: 8 | K35: 8 | N35: 8 | O35: 8 | P35: 8 | Q35: 8 | R35: 8 | S35: =SUM(C35:R35) -> 96
A36: 02100295 | B36: Genil Silva | C36: 8 | D36: 7.68 | G36: 8 | H36: 8 | I36: 8 | J36: 8 | K36: 8 | N36: 8 | O36: 8 | P36: 8 | Q36: 8 | R36: 8 | S36: =SUM(C36:R36) -> 95.68
A37: 01100123 | B37: Gerra Rose Fajardo | C37: 8 | D37: 8 | G37: 8 | H37: 8 | I37: 8 | J37: 8 | K37: 8 | N37: 8 | O37: 8 | P37: 8 | Q37: 8 | S37: =SUM(C37:R37)-R37 -> 88
A38: 01100222 | B38: Glenn Oplado | C38: 7.6 | D38: 8 | G38: 8 | J38: 8 | K38: 8 | N38: 8 | O38: 8 | P38: 8 | Q38: 7.95 | R38: 8 | S38: =SUM(C38:R38) -> 79.55
A39: 02100127 | B39: Hannah Jane Villegas Nocete | C39: 8 | D39: 8 | G39: 8 | H39: 8 | J39: 8 | K39: 8 | N39: 8 | O39: 8 | P39: 8 | Q39: 8 | S39: =SUM(C39:R39) -> 80
A40: 02100128 | B40: Harlley D. Alos | C40: 8 | D40: 8 | G40: 8 | H40: 8 | I40: 8 | J40: 8 | K40: 8 | N40: 8 | O40: 8 | P40: 8 | Q40: 8 | R40: 8 | S40: =SUM(C40:R40) -> 96
...

Sheet Hourly
A1: TGS BPO
A2: =#REF! -> #REF! | B2: Official Role: | C2: =VLOOKUP(A3,#REF!,4,0) -> #REF!
A3: Yendy Christian Sevilla | B3: Site Location: | C3: =VLOOKUP(A3,#REF!,3,0) -> #REF!
B4: Basic Hourly Rate: | C4: =VLOOKUP(A3,#REF!,13,0) -> #REF!
A6: Basic Salary | B6: =VLOOKUP(A3,#REF!,17,0) -> #REF! | C6: hrs | D6: Php | E6: =VLOOKUP(A3,#REF!,18,0) -> #REF!
A7: SIL | B7: =VLOOKUP(A3,#REF!,20,0) -> #REF! | C7: hrs | E7: =VLOOKUP(A3,#REF!,21,0) -> #REF!
A8: Solo Parent/VAWC | B8: =VLOOKUP(A3,#REF!,26,0) -> #REF! | C8: hrs | E8: =VLOOKUP(A3,#REF!,27,0) -> #REF!
A9: Other Leaves(Maternity, Paternity and others) | B9: =VLOOKUP(A3,#REF!,28,0) -> #REF! | C9: hrs | E9: =VLOOKUP(A3,#REF!,29,0) -> #REF!
A10: Reg Overtime (ROT) | B10: =VLOOKUP(A3,#REF!,30,0) -> #REF! | C10: hrs | E10: =VLOOKUP(A3,#REF!,31,0) -> #REF!
A11: Special Hol (SH) Premium | B11: =VLOOKUP(A3,#REF!,32,0) -> #REF! | C11: hrs | E11: =VLOOKUP(A3,#REF!,33,0) -> #REF!
A12: Special Hol OT | B12: =VLOOKUP(A3,#REF!,36,0) -> #REF! | C12: hrs | E12: =VLOOKUP(A3,#REF!,37,0) -> #REF!
A13: Legal Holiday (LH) Premium | B13: =VLOOKUP(A3,#REF!,38,0) -> #REF! | C13: hrs | E13: =VLOOKUP(A3,#REF!,39,0) -> #REF!
A14: LH OT | B14: =VLOOKUP(A3,#REF!,40,0) -> #REF! | C14: hrs | E14: =VLOOKUP(A3,#REF!,41,0) -> #REF!
A15: Rest Day (RDOT) | B15: =VLOOKUP(A3,#REF!,46,0) -> #REF! | C15: hr. | E15: =VLOOKUP(A3,#REF!,47,0) -> #REF!
A16: Night Differential | B16: =VLOOKUP(A3,#REF!,42,0) -> #REF! | C16: hrs | E16: =VLOOKUP(A3,#REF!,43,0) -> #REF!
A17: Referral Bonus | E17: =VLOOKUP(A3,#REF!,45,0) -> #REF!
A18: Complexity Allowance | E18: =VLOOKUP(A3,#REF!,48,0) -> #REF!
A19: Observational Allowance | E19: =VLOOKUP(A3,#REF!,49,0) -> #REF!
A20: Allowance | E20: =VLOOKUP(A3,#REF!,50,0) -> #REF!
A21: KPI/OT Incentive | E21: =VLOOKUP(A3,#REF!,51,0) -> #REF!
A22: Tax Refund
A23: Retro Pay
A24: Salary Adjustment (Dispute) | E24: =VLOOKUP(A3,#REF!,52,0) -> #REF!
E25: =VLOOKUP(A3,#REF!,53,0) -> #REF!
A26: Gross Pay | D26: Php | E26: =ROUND(SUM(E6:E25),2) -> #REF! | F26: =VLOOKUP(A3,#REF!,54,0) -> #REF! | G26: =E26-F26 -> #REF!
A27: DEDUCTIONS:
A28: SSS | E28: =VLOOKUP(A3,#REF!,55,0) -> #REF!
A29: Philhealth | E29: =VLOOKUP(A3,#REF!,56,0) -> #REF!
A30: HDMF | E30: =VLOOKUP(A3,#REF!,57,0) -> #REF!
A31: SSS Salary Loan | E31: =VLOOKUP(A3,#REF!,58,0) -> #REF!
A32: SSS Calamity Loan | E32: =VLOOKUP(A3,#REF!,59,0) -> #REF!
A33: HDMF Multipurpose Loan | E33: =VLOOKUP(A3,#REF!,60,0) -> #REF!
A34: HDMF Calamity Loan | E34: =VLOOKUP(A3,#REF!,61,0) -> #REF!
A35: Tax W/held | E35: =VLOOKUP(A3,#REF!,63,0) -> #REF!
A36: Advances | E36: =VLOOKUP(A3,#REF!,64,0) -> #REF!
A37: Over payment | E37: =VLOOKUP(A3,#REF!,62,0) -> #REF!
A38: HMO | E38: =VLOOKUP(A3,#REF!,65,0) -> #REF!
A39: HMO Dependent | E39: =VLOOKUP(A3,#REF!,66,0) -> #REF! | I39: =VLOOKUP(A3,#REF!,64,0) -> #REF!
A40: Total | D40: Php | E40: =SUM(E28:E39) -> #REF!
A41: NET PAY | D41: Php | E41: =ROUND((E26-E40),2) -> #REF! | F41: =VLOOKUP(A3,#REF!,68,0) -> #REF! | G41: =E41-F41 -> #REF!
...

Sheet OT
A1: Employee ID | B1: Employee Name | C1: RD OT (within first 8hrs) | D1: Regular OT | E1: Special Non Working Holiday OT | F1: Grand Total
A2: 01100240 | B2: Abegail Mandras | C2: 7.93 | D2: 1.99 | F2: =SUM(C2:E2) -> 9.92
A3: 02100227 | B3: April Jane Elnar | D3: 10 | E3: 3 | F3: =SUM(C3:E3) -> 13
A4: 01100108 | B4: Camela Torrate | C4: 8 | D4: 9 | F4: =SUM(C4:E4) -> 17
A5: 02100109 | B5: Candice Kate Velasco | C5: 6 | D5: 7.75 | F5: =SUM(C5:E5) -> 13.75
A6: 01100220 | B6: Christian Pagobo | D6: 4 | F6: =SUM(C6:E6) -> 4
A7: 01100112 | B7: Crislyn Cuizon | C7: 8 | D7: 6.99 | F7: =SUM(C7:E7) -> 14.99
A8: 01100329 | B8: cyriline vergara | D8: 3.5 | F8: =SUM(C8:E8) -> 3.5
A9: 01100113 | B9: Demie Marie Medalle | C9: 5.5 | F9: =SUM(C9:E9) -> 5.5
A10: 01100116 | B10: Donald Bacanaya | C10: 5.5 | F10: =SUM(C10:E10) -> 5.5
A11: 01100253 | B11: Ericka Dorreen Amores - Abejero | E11: 2 | F11: =SUM(C11:E11) -> 2
A12: 01100118 | B12: Fame Diez | D12: 3 | F12: =SUM(C12:E12) -> 3
A13: 01100221 | B13: Farrah Jean Vildosola | D13: 7 | E13: 1 | F13: =SUM(C13:E13) -> 8
A14: 02100119 | B14: Ferreh Jane Vilos | D14: 16 | E14: 4 | F14: =SUM(C14:E14) -> 20
A15: 01100217 | B15: Franklyn Jay Talisic | D15: 4 | F15: =SUM(C15:E15) -> 4
A16: 02100295 | B16: Genil Silva | D16: 9.64 | E16: 1 | F16: =SUM(C16:E16) -> 10.64
A17: 01100222 | B17: Glenn Oplado | D17: 4 | F17: =SUM(C17:E17) -> 4
A18: 02100127 | B18: Hannah Jane Villegas Nocete | C18: 8 | D18: 1 | F18: =SUM(C18:E18) -> 9
A19: 02100141 | B19: john carlo inson | D19: 6 | E19: 0.62 | F19: =SUM(C19:E19) -> 6.62
A20: 01100142 | B20: John Carlos Carillo | D20: 14 | E20: 1 | F20: =SUM(C20:E20) -> 15
A21: 02100149 | B21: Katherine Tiffany Ragay | D21: 8 | E21: 1 | F21: =SUM(C21:E21) -> 9
A22: 01100261 | B22: Kenth Levi Gulbe | D22: 3.7 | F22: =SUM(C22:E22) -> 3.7
A23: 02100151 | B23: Kurt Harem Adalid | D23: 15 | F23: =SUM(C23:E23) -> 15
A24: 02100203 | B24: Kyle Jed B. Cariño | D24: 1 | F24: =SUM(C24:E24) -> 1
A25: 02100229 | B25: Laiza Lunday | D25: 6 | F25: =SUM(C25:E25) -> 6
A26: 01100157 | B26: Ma.Theresa Lapiña | D26: 4 | F26: =SUM(C26:E26) -> 4
A27: 02100160 | B27: Marietta B. Diana | D27: 1 | F27: =SUM(C27:E27) -> 1
A28: 01100161 | B28: Marjorie Tarucan | C28: 4 | D28: 7.5 | E28: 1 | F28: =SUM(C28:E28) -> 12.5
A29: 01100272 | B29: Mary Clere Garciano | D29: 20.87 | E29: 1.9 | F29: =SUM(C29:E29) -> 22.77
A30: 02100173 | B30: Michael Salatan | D30: 6.35 | F30: =SUM(C30:E30) -> 6.35
A31: 02100204 | B31: Nerfe A Palagtiw | D31: 7.5 | E31: 2.5 | F31: =SUM(C31:E31) -> 10
A32: 01100174 | B32: Novem Mae Delito | D32: 1 | F32: =SUM(C32:E32) -> 1
A33: 02100286 | B33: Paul Ryan Generoso | D33: 2 | E33: 2 | F33: =SUM(C33:E33) -> 4
A34: 02100176 | B34: Princes Ann Garcia | D34: 8 | E34: 2 | F34: =SUM(C34:E34) -> 10
A35: 02100283 | B35: Ranel Sarmiento | D35: 2 | E35: 2 | F35: =SUM(C35:E35) -> 4
A36: 01100184 | B36: Sharriz Soterol | C36: 16 | D36: 21.5 | E36: 1 | F36: =SUM(C36:E36) -> 38.5
A37: 02100192 | B37: weeno pagayon | D37: 4.5 | E37: 1.5 | F37: =SUM(C37:E37) -> 6
A38: 02100296 | B38: Yendy Christian Sevilla | D38: 6 | E38: 1 | F38: =SUM(C38:E38) -> 7
B39: Grand Total | C39: =SUM(C2:C38) -> 68.93 | D39: =SUM(D2:D38) -> 233.79 | E39: =SUM(E2:E38) -> 28.52 | F39: =SUM(F2:F38) -> 331.24

Sheet Special Holiday
A1: Emp ID | B1: Employee's Name | C1: Site Location | D1: 45947 | E1: 45961 | F1: Total SH
A2: 01100240 | B2: Abegail Mandras | C2: Cebu | E2: =VLOOKUP(A2,'Total Hours - Summary'!A:R,18,0) -> 8 | F2: =SUM(D2:E2) -> 8
A3: 01100277 | B3: Adrian Lawat | C3: Cebu | E3: =VLOOKUP(A3,'Total Hours - Summary'!A:R,18,0) -> 6.01 | F3: =SUM(D3:E3) -> 6.01
A4: 02100100 | B4: Aillen Joy Largo | C4: Dumaguete | D4: =VLOOKUP(A4,'Total Hours - Summary'!A:D,4,0) -> 8 | E4: =VLOOKUP(A4,'Total Hours - Summary'!A:R,18,0) -> 8 | F4: =SUM(D4:E4) -> 16
A5: 02100334 | B5: Alvin Lozada | C5: DUMAGUETE | D5: =VLOOKUP(A5,'Total Hours - Summary'!A:D,4,0) -> 8 | E5: =VLOOKUP(A5,'Total Hours - Summary'!A:R,18,0) -> 8 | F5: =SUM(D5:E5) -> 16
A6: 01100101 | B6: Andrea Ceniza | C6: Cebu | E6: =VLOOKUP(A6,'Total Hours - Summary'!A:R,18,0) -> 8 | F6: =SUM(D6:E6) -> 8
A7: 02100103 | B7: Angelica Paligsa | C7: Dumaguete | D7: =VLOOKUP(A7,'Total Hours - Summary'!A:D,4,0) -> 8 | E7: =VLOOKUP(A7,'Total Hours - Summary'!A:R,18,0) -> 8 | F7: =SUM(D7:E7) -> 16
A8: 02100104 | B8: Ann Lou Minguito | C8: Dumaguete | D8: =VLOOKUP(A8,'Total Hours - Summary'!A:D,4,0) -> 7.98 | E8: =VLOOKUP(A8,'Total Hours - Summary'!A:R,18,0) -> 8 | F8: =SUM(D8:E8) -> 15.98
A9: 02100227 | B9: April Jane Elnar | C9: Dumaguete | D9: =VLOOKUP(A9,'Total Hours - Summary'!A:D,4,0) -> 8 | E9: =VLOOKUP(A9,'Total Hours - Summary'!A:R,18,0) -> 8 | F9: =SUM(D9:E9) -> 16
A10: 02100194 | B10: April Sanchez | C10: Cebu | E10: =VLOOKUP(A10,'Total Hours - Summary'!A:R,18,0) -> 7.9 | F10: =SUM(D10:E10) -> 7.9
A11: 01100218 | B11: Aquilyn Dayan A. Adlit | C11: Cebu | E11: =VLOOKUP(A11,'Total Hours - Summary'!A:R,18,0) -> 8 | F11: =SUM(D11:E11) -> 8
A12: 02100327 | B12: Ardeth James Ortega | C12: DUMAGUETE | D12: =VLOOKUP(A12,'Total Hours - Summary'!A:D,4,0) -> 8 | E12: =VLOOKUP(A12,'Total Hours - Summary'!A:R,18,0) -> 8 | F12: =SUM(D12:E12) -> 16
A13: 02100107 | B13: Brenda Mae T. Bacurnay | C13: Dumaguete | D13: =VLOOKUP(A13,'Total Hours - Summary'!A:D,4,0) -> 8 | E13: =VLOOKUP(A13,'Total Hours - Summary'!A:R,18,0) -> 8 | F13: =SUM(D13:E13) -> 16
A14: 01100271 | B14: Buenagen Bagundol | C14: Cebu | E14: =VLOOKUP(A14,'Total Hours - Summary'!A:R,18,0) -> 0 | F14: =SUM(D14:E14) -> 0
A15: 01100108 | B15: Camela Torrate | C15: Cebu | E15: =VLOOKUP(A15,'Total Hours - Summary'!A:R,18,0) -> 8 | F15: =SUM(D15:E15) -> 8
A16: 02100109 | B16: Candice Kate Velasco | C16: Dumaguete | D16: =VLOOKUP(A16,'Total Hours - Summary'!A:D,4,0) -> 8 | E16: =VLOOKUP(A16,'Total Hours - Summary'!A:R,18,0) -> 8 | F16: =SUM(D16:E16) -> 16
A17: 02100294 | B17: Carlo John Placino Rubio | C17: Dumaguete | D17: =VLOOKUP(A17,'Total Hours - Summary'!A:D,4,0) -> 8 | E17: =VLOOKUP(A17,'Total Hours - Summary'!A:R,18,0) -> 8 | F17: =SUM(D17:E17) -> 16
A18: 01100270 | B18: Catherine Vergara | C18: Cebu | E18: =VLOOKUP(A18,'Total Hours - Summary'!A:R,18,0) -> 7.88 | F18: =SUM(D18:E18) -> 7.88
A19: 01100220 | B19: Christian Pagobo | C19: Cebu | E19: =VLOOKUP(A19,'Total Hours - Summary'!A:R,18,0) -> 8 | F19: =SUM(D19:E19) -> 8
A20: 01100112 | B20: Crislyn Cuizon | C20: Cebu | E20: =VLOOKUP(A20,'Total Hours - Summary'!A:R,18,0) -> 8 | F20: =SUM(D20:E20) -> 8
A21: 01100329 | B21: Cyriline Vergara | C21: Cebu | E21: =VLOOKUP(A21,'Total Hours - Summary'!A:R,18,0) -> 0 | F21: =SUM(D21:E21) -> 0
A22: 01100113 | B22: Demie Marie Medalle | C22: Cebu | E22: =VLOOKUP(A22,'Total Hours - Summary'!A:R,18,0) -> 8 | F22: =SUM(D22:E22) -> 8
A23: 01100115 | B23: Dharlene G. Bendanillo | C23: Cebu | E23: =VLOOKUP(A23,'Total Hours - Summary'!A:R,18,0) -> 8 | F23: =SUM(D23:E23) -> 8
A24: 01100116 | B24: Donald Bacanaya | C24: Cebu | E24: =VLOOKUP(A24,'Total Hours - Summary'!A:R,18,0) -> 8 | F24: =SUM(D24:E24) -> 8
A25: 01100253 | B25: Ericka Dorreen Abejero | C25: Dumaguete | D25: =VLOOKUP(A25,'Total Hours - Summary'!A:D,4,0) -> 8 | E25: =VLOOKUP(A25,'Total Hours - Summary'!A:R,18,0) -> 7.57 | F25: =SUM(D25:E25) -> 15.57
A26: 02100117 | B26: Ernesto F. Roquin Jr. | C26: Dumaguete | D26: =VLOOKUP(A26,'Total Hours - Summary'!A:D,4,0) -> 8 | E26: =VLOOKUP(A26,'Total Hours - Summary'!A:R,18,0) -> 8 | F26: =SUM(D26:E26) -> 16
A27: 01100118 | B27: Fame Diez | C27: Cebu | E27: =VLOOKUP(A27,'Total Hours - Summary'!A:R,18,0) -> 8 | F27: =SUM(D27:E27) -> 8
A28: 01100221 | B28: Farrah Jean Vildosola | C28: Cebu | E28: =VLOOKUP(A28,'Total Hours - Summary'!A:R,18,0) -> 8 | F28: =SUM(D28:E28) -> 8
A29: 02100119 | B29: Ferreh Jane Vilos | C29: Dumaguete | D29: =VLOOKUP(A29,'Total Hours - Summary'!A:D,4,0) -> 8 | E29: =VLOOKUP(A29,'Total Hours - Summary'!A:R,18,0) -> 8 | F29: =SUM(D29:E29) -> 16
A30: 02100120 | B30: Flint Kaynon Balmadres | C30: Dumaguete | D30: =VLOOKUP(A30,'Total Hours - Summary'!A:D,4,0) -> 8 | E30: =VLOOKUP(A30,'Total Hours - Summary'!A:R,18,0) -> 8 | F30: =SUM(D30:E30) -> 16
A31: 01100217 | B31: Franklyn Jay Talisic | C31: Cebu | E31: =VLOOKUP(A31,'Total Hours - Summary'!A:R,18,0) -> 7.93 | F31: =SUM(D31:E31) -> 7.93
A32: 02100121 | B32: Fritzyl D. Lorico | C32: Dumaguete | D32: =VLOOKUP(A32,'Total Hours - Summary'!A:D,4,0) -> 8 | E32: =VLOOKUP(A32,'Total Hours - Summary'!A:R,18,0) -> 8 | F32: =SUM(D32:E32) -> 16
A33: 02100295 | B33: Genil Silva | C33: Dumaguete | D33: =VLOOKUP(A33,'Total Hours - Summary'!A:D,4,0) -> 7.68 | E33: =VLOOKUP(A33,'Total Hours - Summary'!A:R,18,0) -> 8 | F33: =SUM(D33:E33) -> 15.68
A34: 01100222 | B34: Glenn Oplado | C34: Cebu | E34: =VLOOKUP(A34,'Total Hours - Summary'!A:R,18,0) -> 8 | F34: =SUM(D34:E34) -> 8
A35: 02100127 | B35: Hannah Jane Villegas Nocete | C35: Dumaguete | D35: =VLOOKUP(A35,'Total Hours - Summary'!A:D,4,0) -> 8 | E35: =VLOOKUP(A35,'Total Hours - Summary'!A:R,18,0) -> 0 | F35: =SUM(D35:E35) -> 8
A36: 02100128 | B36: Harlley D. Alos | C36: Dumaguete | D36: =VLOOKUP(A36,'Total Hours - Summary'!A:D,4,0) -> 8 | E36: =VLOOKUP(A36,'Total Hours - Summary'!A:R,18,0) -> 8 | F36: =SUM(D36:E36) -> 16
A37: 02100202 | B37: Heide Camuta | C37: Dumaguete | D37: =VLOOKUP(A37,'Total Hours - Summary'!A:D,4,0) -> 8 | E37: =VLOOKUP(A37,'Total Hours - Summary'!A:R,18,0) -> 8 | F37: =SUM(D37:E37) -> 16
A38: 01100129 | B38: Ingrid Irene Garcia | C38: Cebu | E38: =VLOOKUP(A38,'Total Hours - Summary'!A:R,18,0) -> 8 | F38: =SUM(D38:E38) -> 8
A39: 01100273 | B39: Ira Niña Casiño | C39: Cebu | E39: =VLOOKUP(A39,'Total Hours - Summary'!A:R,18,0) -> 8 | F39: =SUM(D39:E39) -> 8
A40: 02100130 | B40: Jafferson Sojor | C40: Dumaguete | D40: =VLOOKUP(A40,'Total Hours - Summary'!A:D,4,0) -> 8 | E40: =VLOOKUP(A40,'Total Hours - Summary'!A:R,18,0) -> 8 | F40: =SUM(D40:E40) -> 16
...

Sheet SIL_Offset
A1: Employee ID | B1: Employee Name | C1: Compensatory Time Off (CTO) | D1: PH Holidays _ Not Working on a Regular holiday | E1: SIL Credit (Additional based on Tenure) | F1: SIL Credits | G1: Grand Total
A2: 02100103 | B2: Angelica Paligsa | F2: 8 | G2: 8
A3: 02200105 | B3: Anna Marie Tabares | F3: 8 | G3: 8
A4: 02100194 | B4: April Sanchez | F4: 8 | G4: 8
A5: 01100271 | B5: Buenagen Bagundol | F5: 8 | G5: 8
A6: 01100108 | B6: Camela Torrate | F6: 8 | G6: 8
A7: 01100113 | B7: Demie Marie Medalle | F7: 8 | G7: 8
A8: 01100118 | B8: Fame Diez | F8: 8 | G8: 8
A9: 01100123 | B9: Gerra Rose Fajardo | D9: 8 | G9: 8
A10: 01100222 | B10: Glenn Oplado | F10: 16 | G10: 16
A11: 02100127 | B11: Hannah Jane Villegas Nocete | F11: 16 | G11: 16
A12: 02100133 | B12: Janely Nayon | F12: 8 | G12: 8
A13: 01100254 | B13: Jay Michael Decepolo | F13: 16 | G13: 16
A14: 02100135 | B14: Jay Pee Antinero | F14: 4 | G14: 4
A15: 01200137 | B15: Jeramie Oacan | E15: 4 | G15: 4
A16: 01100210 | B16: Joepet Cañete | F16: 8 | G16: 8
A17: 02100140 | B17: Johanna Vierna Anub | F17: 4 | G17: 4
A18: 01200148 | B18: Katherine Maliluya | C18: 8 | G18: 8
A19: 02100150 | B19: Khristel Ann Callao | F19: 8 | G19: 8
A20: 02100151 | B20: Kurt Harem Adalid | F20: 8 | G20: 8
A21: 02100203 | B21: Kyle Jed B. Cariño | F21: 8 | G21: 8
A22: 02100229 | B22: Laiza Lunday | F22: 8 | G22: 8
A23: 02100196 | B23: Marie Vincent Sasan | F23: 16 | G23: 16
A24: 01100239 | B24: Mary Jane Armenion | F24: 32 | G24: 32
A25: 01200168 | B25: Maureen Sollano | F25: 4 | G25: 4
A26: 01100174 | B26: Novem Mae Delito | E26: 8 | F26: 24 | G26: 32
A27: 02100286 | B27: Paul Ryan Generoso | F27: 16 | G27: 16
B28: Grand Total | C28: 8 | D28: 8 | E28: 12 | F28: 252 | G28: 280
